Traceback (most recent call last):
  File "/opt/hostedtoolcache/Python/3.11.8/x64/lib/python3.11/site-packages/jupyter_cache/executors/utils.py", line 58, in single_nb_execution
    executenb(
  File "/opt/hostedtoolcache/Python/3.11.8/x64/lib/python3.11/site-packages/nbclient/client.py", line 1269, in execute
    return NotebookClient(nb=nb, resources=resources, km=km, **kwargs).execute()
           ^^^^^^^^^^^^^^^^^^^^^^^^^^^^^^^^^^^^^^^^^^^^^^^^^^^^^^^^^^^^^^^^^^^^^
  File "/opt/hostedtoolcache/Python/3.11.8/x64/lib/python3.11/site-packages/nbclient/util.py", line 85, in wrapped
    return just_run(coro(*args, **kwargs))
           ^^^^^^^^^^^^^^^^^^^^^^^^^^^^^^^
  File "/opt/hostedtoolcache/Python/3.11.8/x64/lib/python3.11/site-packages/nbclient/util.py", line 60, in just_run
    return loop.run_until_complete(coro)
           ^^^^^^^^^^^^^^^^^^^^^^^^^^^^^
  File "/opt/hostedtoolcache/Python/3.11.8/x64/lib/python3.11/asyncio/base_events.py", line 654, in run_until_complete
    return future.result()
           ^^^^^^^^^^^^^^^
  File "/opt/hostedtoolcache/Python/3.11.8/x64/lib/python3.11/site-packages/nbclient/client.py", line 707, in async_execute
    await self.async_execute_cell(
  File "/opt/hostedtoolcache/Python/3.11.8/x64/lib/python3.11/site-packages/nbclient/client.py", line 1025, in async_execute_cell
    await self._check_raise_for_error(cell, cell_index, exec_reply)
  File "/opt/hostedtoolcache/Python/3.11.8/x64/lib/python3.11/site-packages/nbclient/client.py", line 919, in _check_raise_for_error
    raise CellExecutionError.from_cell_and_msg(cell, exec_reply_content)
nbclient.exceptions.CellExecutionError: An error occurred while executing the following cell:
------------------
with open("files/cid679-vapor-pressure.json", "w") as outfile:
    json.dump(mydata, outfile, indent=4)
------------------

[0;31m---------------------------------------------------------------------------[0m
[0;31mFileNotFoundError[0m                         Traceback (most recent call last)
Cell [0;32mIn[12], line 1[0m
[0;32m----> 1[0m [38;5;28;01mwith[39;00m [38;5;28;43mopen[39;49m[43m([49m[38;5;124;43m"[39;49m[38;5;124;43mfiles/cid679-vapor-pressure.json[39;49m[38;5;124;43m"[39;49m[43m,[49m[43m [49m[38;5;124;43m"[39;49m[38;5;124;43mw[39;49m[38;5;124;43m"[39;49m[43m)[49m [38;5;28;01mas[39;00m outfile:
[1;32m      2[0m     json[38;5;241m.[39mdump(mydata, outfile, indent[38;5;241m=[39m[38;5;241m4[39m)

File [0;32m/opt/hostedtoolcache/Python/3.11.8/x64/lib/python3.11/site-packages/IPython/core/interactiveshell.py:310[0m, in [0;36m_modified_open[0;34m(file, *args, **kwargs)[0m
[1;32m    303[0m [38;5;28;01mif[39;00m file [38;5;129;01min[39;00m {[38;5;241m0[39m, [38;5;241m1[39m, [38;5;241m2[39m}:
[1;32m    304[0m     [38;5;28;01mraise[39;00m [38;5;167;01mValueError[39;00m(
[1;32m    305[0m         [38;5;124mf[39m[38;5;124m"[39m[38;5;124mIPython won[39m[38;5;124m'[39m[38;5;124mt let you open fd=[39m[38;5;132;01m{[39;00mfile[38;5;132;01m}[39;00m[38;5;124m by default [39m[38;5;124m"[39m
[1;32m    306[0m         [38;5;124m"[39m[38;5;124mas it is likely to crash IPython. If you know what you are doing, [39m[38;5;124m"[39m
[1;32m    307[0m         [38;5;124m"[39m[38;5;124myou can use builtins[39m[38;5;124m'[39m[38;5;124m open.[39m[38;5;124m"[39m
[1;32m    308[0m     )
[0;32m--> 310[0m [38;5;28;01mreturn[39;00m [43mio_open[49m[43m([49m[43mfile[49m[43m,[49m[43m [49m[38;5;241;43m*[39;49m[43margs[49m[43m,[49m[43m [49m[38;5;241;43m*[39;49m[38;5;241;43m*[39;49m[43mkwargs[49m[43m)[49m

[0;31mFileNotFoundError[0m: [Errno 2] No such file or directory: 'files/cid679-vapor-pressure.json'
FileNotFoundError: [Errno 2] No such file or directory: 'files/cid679-vapor-pressure.json'

